From data collection to prediction, 6 seconds have elapsed
Last timestamp in scoring data: 1533640139.999 compared to current timestamp: 1533640181.520383 with 41.52133011817932 diff
2018-08-07 21:03:18
Buying with predicted 25 min return of: 0.9807481631275204
Traceback (most recent call last):
  File "src/the_logic/market_maker_trader.py", line 208, in <module>
    main()
  File "src/the_logic/market_maker_trader.py", line 30, in main
    logic(iter_)
  File "src/the_logic/market_maker_trader.py", line 93, in logic
    buy_order = mm_scoring.bnb_client.order_market_buy(symbol=mm_scoring.target_coin.upper(), quantity=trade_qty, newOrderRespType='FULL')
  File "/usr/local/anaconda/lib/python3.6/site-packages/binance/client.py", line 1215, in order_market_buy
    return self.order_market(**params)
  File "/usr/local/anaconda/lib/python3.6/site-packages/binance/client.py", line 1189, in order_market
    return self.create_order(**params)
  File "/usr/local/anaconda/lib/python3.6/site-packages/binance/client.py", line 1054, in create_order
    return self._post('order', True, data=params)
  File "/usr/local/anaconda/lib/python3.6/site-packages/binance/client.py", line 209, in _post
    return self._request_api('post', path, signed, version, **kwargs)
  File "/usr/local/anaconda/lib/python3.6/site-packages/binance/client.py", line 180, in _request_api
    return self._request(method, uri, signed, **kwargs)
  File "/usr/local/anaconda/lib/python3.6/site-packages/binance/client.py", line 175, in _request
    return self._handle_response(response)
  File "/usr/local/anaconda/lib/python3.6/site-packages/binance/client.py", line 199, in _handle_response
    raise BinanceAPIException(response)
binance.exceptions.BinanceAPIException: APIError(code=-1013): Filter failure: LOT_SIZE
Failed with exit code: 1
